2020-04-26 08:12:20,854 [INFO] root consoleworker.py:434	Log file created
2020-04-26 08:12:20,855 [INFO] root consoleworker.py:438	Logging handler <logging.FileHandler object at 0x7f5a702b7c90> added
2020-04-26 08:12:20,856 [INFO] root consoleworker.py:438	Logging handler <logging.StreamHandler object at 0x7f5a702fd8d0> added
2020-04-26 08:12:20,857 [INFO] root consoleworker.py:438	Logging handler <logging.StreamHandler object at 0x7f5a702a3ad0> added
2020-04-26 08:12:20,857 [INFO] root consoleworker.py:373	Created a folder for the test. /var/loadtest/logs/2020-04-26_08-12-20.808770
2020-04-26 08:12:20,858 [INFO] yandextank.core.tankcore tankcore.py:237	Configuring plugins...
2020-04-26 08:12:20,859 [INFO] yandextank.core.tankcore tankcore.py:190	Loading plugins...
2020-04-26 08:12:20,859 [DEBUG] yandextank.core.tankcore tankcore.py:192	Loading plugin phantom from yandextank.plugins.Phantom
2020-04-26 08:12:20,860 [DEBUG] yandextank.core.tankcore tankcore.py:192	Loading plugin rcheck from yandextank.plugins.ResourceCheck
2020-04-26 08:12:20,860 [DEBUG] yandextank.core.tankcore tankcore.py:192	Loading plugin json_report from yandextank.plugins.JsonReport
2020-04-26 08:12:20,864 [DEBUG] yandextank.core.tankcore tankcore.py:192	Loading plugin rcassert from yandextank.plugins.RCAssert
2020-04-26 08:12:20,864 [DEBUG] yandextank.core.tankcore tankcore.py:192	Loading plugin console from yandextank.plugins.Console
2020-04-26 08:12:20,864 [DEBUG] yandextank.core.tankcore tankcore.py:192	Loading plugin shellexec from yandextank.plugins.ShellExec
2020-04-26 08:12:20,865 [DEBUG] yandextank.core.tankcore tankcore.py:192	Loading plugin autostop from yandextank.plugins.Autostop
2020-04-26 08:12:20,865 [DEBUG] yandextank.core.tankcore tankcore.py:212	Plugin instances: {'plugin_phantom': <yandextank.plugins.Phantom.plugin.Plugin object at 0x7f5a6ffdae10>, 'plugin_autostop': <yandextank.plugins.Autostop.plugin.Plugin object at 0x7f5a6ffda250>, 'plugin_shellexec': <yandextank.plugins.ShellExec.plugin.Plugin object at 0x7f5a6ffdae50>, 'plugin_console': <yandextank.plugins.Console.plugin.Plugin object at 0x7f5a6ffdad90>, 'plugin_rcassert': <yandextank.plugins.RCAssert.plugin.Plugin object at 0x7f5a6ffdaad0>, 'plugin_rcheck': <yandextank.plugins.ResourceCheck.plugin.Plugin object at 0x7f5a6ffdab50>, 'plugin_json_report': <yandextank.plugins.JsonReport.plugin.Plugin object at 0x7f5a7031ca90>}
2020-04-26 08:12:20,865 [DEBUG] yandextank.core.tankcore tankcore.py:244	Configuring <yandextank.plugins.Phantom.plugin.Plugin object at 0x7f5a6ffdae10>
2020-04-26 08:12:20,866 [DEBUG] yandextank.core.tankcore tankcore.py:391	Searching for plugin: <class 'yandextank.plugins.Autostop.plugin.Plugin'>
2020-04-26 08:12:20,951 [DEBUG] yandextank.core.tankcore tankcore.py:446	Adding artifact file to collect (keep=False): /var/loadtest/logs/2020-04-26_08-12-20.808770/answ_A99p0W.log
2020-04-26 08:12:20,952 [DEBUG] yandextank.core.tankcore tankcore.py:446	Adding artifact file to collect (keep=False): /var/loadtest/logs/2020-04-26_08-12-20.808770/phout_shuZKG.log
2020-04-26 08:12:20,953 [DEBUG] yandextank.core.tankcore tankcore.py:446	Adding artifact file to collect (keep=False): /var/loadtest/logs/2020-04-26_08-12-20.808770/phantom_stat_pSfaBG.log
2020-04-26 08:12:20,955 [DEBUG] yandextank.core.tankcore tankcore.py:446	Adding artifact file to collect (keep=False): /var/loadtest/logs/2020-04-26_08-12-20.808770/phantom_4JJz8L.log
2020-04-26 08:12:20,955 [DEBUG] yandextank.common.util util.py:479	Trying to resolve address string: auditbase_rest
2020-04-26 08:12:20,956 [DEBUG] yandextank.common.util util.py:516	Parsing port
2020-04-26 08:12:20,961 [DEBUG] yandextank.common.util util.py:527	Lookup result: [(2, 1, 6, '', ('192.168.32.5', 0)), (2, 2, 17, '', ('192.168.32.5', 0)), (2, 3, 0, '', ('192.168.32.5', 0))]
2020-04-26 08:12:20,962 [INFO] yandextank.common.util util.py:546	Testing connection to resolved address 192.168.32.5 and port 80
2020-04-26 08:12:20,964 [DEBUG] yandextank.common.util util.py:565	Exception on connect attempt [192.168.32.5]:80 : Traceback (most recent call last):
  File "/usr/local/lib/python2.7/dist-packages/yandextank/common/util.py", line 561, in __test
    test_sock.connect(sa)
  File "/usr/lib/python2.7/socket.py", line 228, in meth
    return getattr(self._sock,name)(*args)
error: [Errno 111] Connection refused

2020-04-26 08:12:20,964 [INFO] yandextank.common.util util.py:549	Failed TCP connection test using [192.168.32.5]:80
2020-04-26 08:12:20,965 [DEBUG] yandextank.common.util util.py:550	Failed TCP connection test using [192.168.32.5]:80
Traceback (most recent call last):
  File "/usr/local/lib/python2.7/dist-packages/yandextank/common/util.py", line 547, in resolve
    self.__test(family, (parsed_ip, port))
  File "/usr/local/lib/python2.7/dist-packages/yandextank/common/util.py", line 567, in __test
    raise RuntimeError(msg % (sa[0], sa[1]))
RuntimeError: TCP Connection test failed for [192.168.32.5]:80, use phantom.connection_test=0 to disable it
2020-04-26 08:12:20,965 [INFO] yandextank.common.util util.py:546	Testing connection to resolved address 192.168.32.5 and port 80
2020-04-26 08:12:20,966 [DEBUG] yandextank.common.util util.py:565	Exception on connect attempt [192.168.32.5]:80 : Traceback (most recent call last):
  File "/usr/local/lib/python2.7/dist-packages/yandextank/common/util.py", line 561, in __test
    test_sock.connect(sa)
  File "/usr/lib/python2.7/socket.py", line 228, in meth
    return getattr(self._sock,name)(*args)
error: [Errno 111] Connection refused

2020-04-26 08:12:20,967 [INFO] yandextank.common.util util.py:549	Failed TCP connection test using [192.168.32.5]:80
2020-04-26 08:12:20,967 [DEBUG] yandextank.common.util util.py:550	Failed TCP connection test using [192.168.32.5]:80
Traceback (most recent call last):
  File "/usr/local/lib/python2.7/dist-packages/yandextank/common/util.py", line 547, in resolve
    self.__test(family, (parsed_ip, port))
  File "/usr/local/lib/python2.7/dist-packages/yandextank/common/util.py", line 567, in __test
    raise RuntimeError(msg % (sa[0], sa[1]))
RuntimeError: TCP Connection test failed for [192.168.32.5]:80, use phantom.connection_test=0 to disable it
2020-04-26 08:12:20,967 [INFO] yandextank.common.util util.py:546	Testing connection to resolved address 192.168.32.5 and port 80
2020-04-26 08:12:20,968 [DEBUG] yandextank.common.util util.py:565	Exception on connect attempt [192.168.32.5]:80 : Traceback (most recent call last):
  File "/usr/local/lib/python2.7/dist-packages/yandextank/common/util.py", line 561, in __test
    test_sock.connect(sa)
  File "/usr/lib/python2.7/socket.py", line 228, in meth
    return getattr(self._sock,name)(*args)
error: [Errno 111] Connection refused

2020-04-26 08:12:20,968 [INFO] yandextank.common.util util.py:549	Failed TCP connection test using [192.168.32.5]:80
2020-04-26 08:12:20,969 [DEBUG] yandextank.common.util util.py:550	Failed TCP connection test using [192.168.32.5]:80
Traceback (most recent call last):
  File "/usr/local/lib/python2.7/dist-packages/yandextank/common/util.py", line 547, in resolve
    self.__test(family, (parsed_ip, port))
  File "/usr/local/lib/python2.7/dist-packages/yandextank/common/util.py", line 567, in __test
    raise RuntimeError(msg % (sa[0], sa[1]))
RuntimeError: TCP Connection test failed for [192.168.32.5]:80, use phantom.connection_test=0 to disable it
2020-04-26 08:12:20,972 [ERROR] root consoleworker.py:268	Exception occurred:
<type 'exceptions.RuntimeError'>: All connection attempts failed for auditbase_rest, use {phantom.connection_test: false} to disable it
  File "/usr/local/lib/python2.7/dist-packages/yandextank/core/consoleworker.py", line 375, in run
    self.core.plugins_configure()

  File "/usr/local/lib/python2.7/dist-packages/yandextank/core/tankcore.py", line 245, in plugins_configure
    plugin.configure()

  File "/usr/local/lib/python2.7/dist-packages/yandextank/plugins/Phantom/plugin.py", line 72, in configure
    self.phantom_config = self.phantom.config_file

  File "/usr/local/lib/python2.7/dist-packages/yandextank/plugins/Phantom/plugin.py", line 81, in phantom
    self._phantom.read_config()

  File "/usr/local/lib/python2.7/dist-packages/yandextank/plugins/Phantom/utils.py", line 95, in read_config
    stream.read_config()

  File "/usr/local/lib/python2.7/dist-packages/yandextank/plugins/Phantom/utils.py", line 275, in read_config
    self.address, do_test_connect, explicit_port)

  File "/usr/local/lib/python2.7/dist-packages/yandextank/common/util.py", line 555, in resolve
    raise RuntimeError(msg % address_str)

2020-04-26 08:12:20,974 [INFO] root consoleworker.py:269	Trying to clean up
2020-04-26 08:12:20,974 [INFO] yandextank.core.tankcore tankcore.py:561	Releasing lock: /var/lock/lunapark_qv3khJ.lock
2020-04-26 08:12:20,977 [WARNING] root consoleworker.py:408	Job number is not available yet
2020-04-26 08:12:20,978 [WARNING] root consoleworker.py:415	Job number is not available yet
2020-04-26 08:12:20,982 [DEBUG] yandextank.core.tankcore tankcore.py:367	Collecting artifacts
2020-04-26 08:12:20,983 [INFO] yandextank.core.tankcore tankcore.py:368	Artifacts dir: /var/loadtest/logs/2020-04-26_08-12-20.808770
2020-04-26 08:12:20,983 [DEBUG] yandextank.core.tankcore tankcore.py:422	Collecting file: /var/loadtest/logs/2020-04-26_08-12-20.808770/phantom_stat_pSfaBG.log to /var/loadtest/logs/2020-04-26_08-12-20.808770/phantom_stat_pSfaBG.log
2020-04-26 08:12:20,985 [WARNING] yandextank.core.tankcore tankcore.py:429	File already exists: /var/loadtest/logs/2020-04-26_08-12-20.808770/phantom_stat_pSfaBG.log
2020-04-26 08:12:20,986 [DEBUG] yandextank.core.tankcore tankcore.py:422	Collecting file: /var/loadtest/logs/2020-04-26_08-12-20.808770/phout_shuZKG.log to /var/loadtest/logs/2020-04-26_08-12-20.808770/phout_shuZKG.log
2020-04-26 08:12:20,989 [WARNING] yandextank.core.tankcore tankcore.py:429	File already exists: /var/loadtest/logs/2020-04-26_08-12-20.808770/phout_shuZKG.log
2020-04-26 08:12:20,991 [DEBUG] yandextank.core.tankcore tankcore.py:422	Collecting file: validation_error.yaml to /var/loadtest/logs/2020-04-26_08-12-20.808770/validation_error.yaml
2020-04-26 08:12:20,992 [WARNING] yandextank.core.tankcore tankcore.py:424	File not found to collect: validation_error.yaml
2020-04-26 08:12:20,993 [DEBUG] yandextank.core.tankcore tankcore.py:422	Collecting file: /var/loadtest/logs/2020-04-26_08-12-20.808770/answ_A99p0W.log to /var/loadtest/logs/2020-04-26_08-12-20.808770/answ_A99p0W.log
2020-04-26 08:12:20,996 [WARNING] yandextank.core.tankcore tankcore.py:429	File already exists: /var/loadtest/logs/2020-04-26_08-12-20.808770/answ_A99p0W.log
2020-04-26 08:12:20,998 [DEBUG] yandextank.core.tankcore tankcore.py:422	Collecting file: /var/loadtest/logs/2020-04-26_08-12-20.808770/phantom_4JJz8L.log to /var/loadtest/logs/2020-04-26_08-12-20.808770/phantom_4JJz8L.log
2020-04-26 08:12:21,001 [WARNING] yandextank.core.tankcore tankcore.py:429	File already exists: /var/loadtest/logs/2020-04-26_08-12-20.808770/phantom_4JJz8L.log
