2020-04-20 09:07:49,790	Exception occurred:
<type 'exceptions.RuntimeError'>: All connection attempts failed for auditbase_rest, use {phantom.connection_test: false} to disable it
  File "/usr/local/lib/python2.7/dist-packages/yandextank/core/consoleworker.py", line 375, in run
    self.core.plugins_configure()

  File "/usr/local/lib/python2.7/dist-packages/yandextank/core/tankcore.py", line 245, in plugins_configure
    plugin.configure()

  File "/usr/local/lib/python2.7/dist-packages/yandextank/plugins/Phantom/plugin.py", line 72, in configure
    self.phantom_config = self.phantom.config_file

  File "/usr/local/lib/python2.7/dist-packages/yandextank/plugins/Phantom/plugin.py", line 81, in phantom
    self._phantom.read_config()

  File "/usr/local/lib/python2.7/dist-packages/yandextank/plugins/Phantom/utils.py", line 95, in read_config
    stream.read_config()

  File "/usr/local/lib/python2.7/dist-packages/yandextank/plugins/Phantom/utils.py", line 275, in read_config
    self.address, do_test_connect, explicit_port)

  File "/usr/local/lib/python2.7/dist-packages/yandextank/common/util.py", line 555, in resolve
    raise RuntimeError(msg % address_str)

2020-04-20 09:07:49,802	Job number is not available yet
2020-04-20 09:07:49,804	Job number is not available yet
2020-04-20 09:07:49,822	File already exists: /var/loadtest/logs/2020-04-20_09-07-49.671641/phantom_nZti0R.log
2020-04-20 09:07:49,827	File already exists: /var/loadtest/logs/2020-04-20_09-07-49.671641/answ_p9amSV.log
2020-04-20 09:07:49,836	File already exists: /var/loadtest/logs/2020-04-20_09-07-49.671641/phantom_stat_Plh9H6.log
2020-04-20 09:07:49,841	File not found to collect: validation_error.yaml
2020-04-20 09:07:49,847	File already exists: /var/loadtest/logs/2020-04-20_09-07-49.671641/phout_7Bklpm.log
2020-04-20 09:13:33,554	Exception occurred:
<type 'exceptions.RuntimeError'>: All connection attempts failed for auditbase_rest, use {phantom.connection_test: false} to disable it
  File "/usr/local/lib/python2.7/dist-packages/yandextank/core/consoleworker.py", line 375, in run
    self.core.plugins_configure()

  File "/usr/local/lib/python2.7/dist-packages/yandextank/core/tankcore.py", line 245, in plugins_configure
    plugin.configure()

  File "/usr/local/lib/python2.7/dist-packages/yandextank/plugins/Phantom/plugin.py", line 72, in configure
    self.phantom_config = self.phantom.config_file

  File "/usr/local/lib/python2.7/dist-packages/yandextank/plugins/Phantom/plugin.py", line 81, in phantom
    self._phantom.read_config()

  File "/usr/local/lib/python2.7/dist-packages/yandextank/plugins/Phantom/utils.py", line 95, in read_config
    stream.read_config()

  File "/usr/local/lib/python2.7/dist-packages/yandextank/plugins/Phantom/utils.py", line 275, in read_config
    self.address, do_test_connect, explicit_port)

  File "/usr/local/lib/python2.7/dist-packages/yandextank/common/util.py", line 555, in resolve
    raise RuntimeError(msg % address_str)

2020-04-20 09:13:33,560	Job number is not available yet
2020-04-20 09:13:33,561	Job number is not available yet
2020-04-20 09:13:33,574	File already exists: /var/loadtest/logs/2020-04-20_09-13-33.435105/phantom_stat_rz90Oe.log
2020-04-20 09:13:33,578	File already exists: /var/loadtest/logs/2020-04-20_09-13-33.435105/answ_CzfGQ_.log
2020-04-20 09:13:33,582	File already exists: /var/loadtest/logs/2020-04-20_09-13-33.435105/phout_P5fDG_.log
2020-04-20 09:13:33,586	File not found to collect: validation_error.yaml
2020-04-20 09:13:33,592	File already exists: /var/loadtest/logs/2020-04-20_09-13-33.435105/phantom_abaCmT.log
2020-04-26 08:12:20,972	Exception occurred:
<type 'exceptions.RuntimeError'>: All connection attempts failed for auditbase_rest, use {phantom.connection_test: false} to disable it
  File "/usr/local/lib/python2.7/dist-packages/yandextank/core/consoleworker.py", line 375, in run
    self.core.plugins_configure()

  File "/usr/local/lib/python2.7/dist-packages/yandextank/core/tankcore.py", line 245, in plugins_configure
    plugin.configure()

  File "/usr/local/lib/python2.7/dist-packages/yandextank/plugins/Phantom/plugin.py", line 72, in configure
    self.phantom_config = self.phantom.config_file

  File "/usr/local/lib/python2.7/dist-packages/yandextank/plugins/Phantom/plugin.py", line 81, in phantom
    self._phantom.read_config()

  File "/usr/local/lib/python2.7/dist-packages/yandextank/plugins/Phantom/utils.py", line 95, in read_config
    stream.read_config()

  File "/usr/local/lib/python2.7/dist-packages/yandextank/plugins/Phantom/utils.py", line 275, in read_config
    self.address, do_test_connect, explicit_port)

  File "/usr/local/lib/python2.7/dist-packages/yandextank/common/util.py", line 555, in resolve
    raise RuntimeError(msg % address_str)

2020-04-26 08:12:20,977	Job number is not available yet
2020-04-26 08:12:20,978	Job number is not available yet
2020-04-26 08:12:20,985	File already exists: /var/loadtest/logs/2020-04-26_08-12-20.808770/phantom_stat_pSfaBG.log
2020-04-26 08:12:20,989	File already exists: /var/loadtest/logs/2020-04-26_08-12-20.808770/phout_shuZKG.log
2020-04-26 08:12:20,992	File not found to collect: validation_error.yaml
2020-04-26 08:12:20,996	File already exists: /var/loadtest/logs/2020-04-26_08-12-20.808770/answ_A99p0W.log
2020-04-26 08:12:21,001	File already exists: /var/loadtest/logs/2020-04-26_08-12-20.808770/phantom_4JJz8L.log
