2020-04-20 09:13:33,485 [INFO] root consoleworker.py:434	Log file created
2020-04-20 09:13:33,487 [INFO] root consoleworker.py:438	Logging handler <logging.FileHandler object at 0x7f9216f31c90> added
2020-04-20 09:13:33,488 [INFO] root consoleworker.py:438	Logging handler <logging.StreamHandler object at 0x7f9216f778d0> added
2020-04-20 09:13:33,489 [INFO] root consoleworker.py:438	Logging handler <logging.StreamHandler object at 0x7f9216f1dad0> added
2020-04-20 09:13:33,490 [INFO] root consoleworker.py:373	Created a folder for the test. /var/loadtest/logs/2020-04-20_09-13-33.435105
2020-04-20 09:13:33,491 [INFO] yandextank.core.tankcore tankcore.py:237	Configuring plugins...
2020-04-20 09:13:33,492 [INFO] yandextank.core.tankcore tankcore.py:190	Loading plugins...
2020-04-20 09:13:33,494 [DEBUG] yandextank.core.tankcore tankcore.py:192	Loading plugin phantom from yandextank.plugins.Phantom
2020-04-20 09:13:33,495 [DEBUG] yandextank.core.tankcore tankcore.py:192	Loading plugin rcheck from yandextank.plugins.ResourceCheck
2020-04-20 09:13:33,495 [DEBUG] yandextank.core.tankcore tankcore.py:192	Loading plugin json_report from yandextank.plugins.JsonReport
2020-04-20 09:13:33,503 [DEBUG] yandextank.core.tankcore tankcore.py:192	Loading plugin rcassert from yandextank.plugins.RCAssert
2020-04-20 09:13:33,505 [DEBUG] yandextank.core.tankcore tankcore.py:192	Loading plugin console from yandextank.plugins.Console
2020-04-20 09:13:33,506 [DEBUG] yandextank.core.tankcore tankcore.py:192	Loading plugin shellexec from yandextank.plugins.ShellExec
2020-04-20 09:13:33,507 [DEBUG] yandextank.core.tankcore tankcore.py:192	Loading plugin autostop from yandextank.plugins.Autostop
2020-04-20 09:13:33,508 [DEBUG] yandextank.core.tankcore tankcore.py:212	Plugin instances: {'plugin_phantom': <yandextank.plugins.Phantom.plugin.Plugin object at 0x7f9216c54e10>, 'plugin_autostop': <yandextank.plugins.Autostop.plugin.Plugin object at 0x7f9216c54250>, 'plugin_shellexec': <yandextank.plugins.ShellExec.plugin.Plugin object at 0x7f9216c54e50>, 'plugin_console': <yandextank.plugins.Console.plugin.Plugin object at 0x7f9216c54d90>, 'plugin_rcassert': <yandextank.plugins.RCAssert.plugin.Plugin object at 0x7f9216c54ad0>, 'plugin_rcheck': <yandextank.plugins.ResourceCheck.plugin.Plugin object at 0x7f9216c54b50>, 'plugin_json_report': <yandextank.plugins.JsonReport.plugin.Plugin object at 0x7f9216f96a90>}
2020-04-20 09:13:33,509 [DEBUG] yandextank.core.tankcore tankcore.py:244	Configuring <yandextank.plugins.Phantom.plugin.Plugin object at 0x7f9216c54e10>
2020-04-20 09:13:33,511 [DEBUG] yandextank.core.tankcore tankcore.py:391	Searching for plugin: <class 'yandextank.plugins.Autostop.plugin.Plugin'>
2020-04-20 09:13:33,523 [DEBUG] yandextank.core.tankcore tankcore.py:446	Adding artifact file to collect (keep=False): /var/loadtest/logs/2020-04-20_09-13-33.435105/answ_CzfGQ_.log
2020-04-20 09:13:33,528 [DEBUG] yandextank.core.tankcore tankcore.py:446	Adding artifact file to collect (keep=False): /var/loadtest/logs/2020-04-20_09-13-33.435105/phout_P5fDG_.log
2020-04-20 09:13:33,529 [DEBUG] yandextank.core.tankcore tankcore.py:446	Adding artifact file to collect (keep=False): /var/loadtest/logs/2020-04-20_09-13-33.435105/phantom_stat_rz90Oe.log
2020-04-20 09:13:33,532 [DEBUG] yandextank.core.tankcore tankcore.py:446	Adding artifact file to collect (keep=False): /var/loadtest/logs/2020-04-20_09-13-33.435105/phantom_abaCmT.log
2020-04-20 09:13:33,533 [DEBUG] yandextank.common.util util.py:479	Trying to resolve address string: auditbase_rest
2020-04-20 09:13:33,535 [DEBUG] yandextank.common.util util.py:516	Parsing port
2020-04-20 09:13:33,541 [DEBUG] yandextank.common.util util.py:527	Lookup result: [(2, 1, 6, '', ('192.168.32.5', 0)), (2, 2, 17, '', ('192.168.32.5', 0)), (2, 3, 0, '', ('192.168.32.5', 0))]
2020-04-20 09:13:33,542 [INFO] yandextank.common.util util.py:546	Testing connection to resolved address 192.168.32.5 and port 80
2020-04-20 09:13:33,545 [DEBUG] yandextank.common.util util.py:565	Exception on connect attempt [192.168.32.5]:80 : Traceback (most recent call last):
  File "/usr/local/lib/python2.7/dist-packages/yandextank/common/util.py", line 561, in __test
    test_sock.connect(sa)
  File "/usr/lib/python2.7/socket.py", line 228, in meth
    return getattr(self._sock,name)(*args)
error: [Errno 111] Connection refused

2020-04-20 09:13:33,545 [INFO] yandextank.common.util util.py:549	Failed TCP connection test using [192.168.32.5]:80
2020-04-20 09:13:33,546 [DEBUG] yandextank.common.util util.py:550	Failed TCP connection test using [192.168.32.5]:80
Traceback (most recent call last):
  File "/usr/local/lib/python2.7/dist-packages/yandextank/common/util.py", line 547, in resolve
    self.__test(family, (parsed_ip, port))
  File "/usr/local/lib/python2.7/dist-packages/yandextank/common/util.py", line 567, in __test
    raise RuntimeError(msg % (sa[0], sa[1]))
RuntimeError: TCP Connection test failed for [192.168.32.5]:80, use phantom.connection_test=0 to disable it
2020-04-20 09:13:33,547 [INFO] yandextank.common.util util.py:546	Testing connection to resolved address 192.168.32.5 and port 80
2020-04-20 09:13:33,548 [DEBUG] yandextank.common.util util.py:565	Exception on connect attempt [192.168.32.5]:80 : Traceback (most recent call last):
  File "/usr/local/lib/python2.7/dist-packages/yandextank/common/util.py", line 561, in __test
    test_sock.connect(sa)
  File "/usr/lib/python2.7/socket.py", line 228, in meth
    return getattr(self._sock,name)(*args)
error: [Errno 111] Connection refused

2020-04-20 09:13:33,549 [INFO] yandextank.common.util util.py:549	Failed TCP connection test using [192.168.32.5]:80
2020-04-20 09:13:33,550 [DEBUG] yandextank.common.util util.py:550	Failed TCP connection test using [192.168.32.5]:80
Traceback (most recent call last):
  File "/usr/local/lib/python2.7/dist-packages/yandextank/common/util.py", line 547, in resolve
    self.__test(family, (parsed_ip, port))
  File "/usr/local/lib/python2.7/dist-packages/yandextank/common/util.py", line 567, in __test
    raise RuntimeError(msg % (sa[0], sa[1]))
RuntimeError: TCP Connection test failed for [192.168.32.5]:80, use phantom.connection_test=0 to disable it
2020-04-20 09:13:33,550 [INFO] yandextank.common.util util.py:546	Testing connection to resolved address 192.168.32.5 and port 80
2020-04-20 09:13:33,551 [DEBUG] yandextank.common.util util.py:565	Exception on connect attempt [192.168.32.5]:80 : Traceback (most recent call last):
  File "/usr/local/lib/python2.7/dist-packages/yandextank/common/util.py", line 561, in __test
    test_sock.connect(sa)
  File "/usr/lib/python2.7/socket.py", line 228, in meth
    return getattr(self._sock,name)(*args)
error: [Errno 111] Connection refused

2020-04-20 09:13:33,552 [INFO] yandextank.common.util util.py:549	Failed TCP connection test using [192.168.32.5]:80
2020-04-20 09:13:33,553 [DEBUG] yandextank.common.util util.py:550	Failed TCP connection test using [192.168.32.5]:80
Traceback (most recent call last):
  File "/usr/local/lib/python2.7/dist-packages/yandextank/common/util.py", line 547, in resolve
    self.__test(family, (parsed_ip, port))
  File "/usr/local/lib/python2.7/dist-packages/yandextank/common/util.py", line 567, in __test
    raise RuntimeError(msg % (sa[0], sa[1]))
RuntimeError: TCP Connection test failed for [192.168.32.5]:80, use phantom.connection_test=0 to disable it
2020-04-20 09:13:33,554 [ERROR] root consoleworker.py:268	Exception occurred:
<type 'exceptions.RuntimeError'>: All connection attempts failed for auditbase_rest, use {phantom.connection_test: false} to disable it
  File "/usr/local/lib/python2.7/dist-packages/yandextank/core/consoleworker.py", line 375, in run
    self.core.plugins_configure()

  File "/usr/local/lib/python2.7/dist-packages/yandextank/core/tankcore.py", line 245, in plugins_configure
    plugin.configure()

  File "/usr/local/lib/python2.7/dist-packages/yandextank/plugins/Phantom/plugin.py", line 72, in configure
    self.phantom_config = self.phantom.config_file

  File "/usr/local/lib/python2.7/dist-packages/yandextank/plugins/Phantom/plugin.py", line 81, in phantom
    self._phantom.read_config()

  File "/usr/local/lib/python2.7/dist-packages/yandextank/plugins/Phantom/utils.py", line 95, in read_config
    stream.read_config()

  File "/usr/local/lib/python2.7/dist-packages/yandextank/plugins/Phantom/utils.py", line 275, in read_config
    self.address, do_test_connect, explicit_port)

  File "/usr/local/lib/python2.7/dist-packages/yandextank/common/util.py", line 555, in resolve
    raise RuntimeError(msg % address_str)

2020-04-20 09:13:33,556 [INFO] root consoleworker.py:269	Trying to clean up
2020-04-20 09:13:33,556 [INFO] yandextank.core.tankcore tankcore.py:561	Releasing lock: /var/lock/lunapark_g0JpeC.lock
2020-04-20 09:13:33,560 [WARNING] root consoleworker.py:408	Job number is not available yet
2020-04-20 09:13:33,561 [WARNING] root consoleworker.py:415	Job number is not available yet
2020-04-20 09:13:33,568 [DEBUG] yandextank.core.tankcore tankcore.py:367	Collecting artifacts
2020-04-20 09:13:33,570 [INFO] yandextank.core.tankcore tankcore.py:368	Artifacts dir: /var/loadtest/logs/2020-04-20_09-13-33.435105
2020-04-20 09:13:33,571 [DEBUG] yandextank.core.tankcore tankcore.py:422	Collecting file: /var/loadtest/logs/2020-04-20_09-13-33.435105/phantom_stat_rz90Oe.log to /var/loadtest/logs/2020-04-20_09-13-33.435105/phantom_stat_rz90Oe.log
2020-04-20 09:13:33,574 [WARNING] yandextank.core.tankcore tankcore.py:429	File already exists: /var/loadtest/logs/2020-04-20_09-13-33.435105/phantom_stat_rz90Oe.log
2020-04-20 09:13:33,576 [DEBUG] yandextank.core.tankcore tankcore.py:422	Collecting file: /var/loadtest/logs/2020-04-20_09-13-33.435105/answ_CzfGQ_.log to /var/loadtest/logs/2020-04-20_09-13-33.435105/answ_CzfGQ_.log
2020-04-20 09:13:33,578 [WARNING] yandextank.core.tankcore tankcore.py:429	File already exists: /var/loadtest/logs/2020-04-20_09-13-33.435105/answ_CzfGQ_.log
2020-04-20 09:13:33,579 [DEBUG] yandextank.core.tankcore tankcore.py:422	Collecting file: /var/loadtest/logs/2020-04-20_09-13-33.435105/phout_P5fDG_.log to /var/loadtest/logs/2020-04-20_09-13-33.435105/phout_P5fDG_.log
2020-04-20 09:13:33,582 [WARNING] yandextank.core.tankcore tankcore.py:429	File already exists: /var/loadtest/logs/2020-04-20_09-13-33.435105/phout_P5fDG_.log
2020-04-20 09:13:33,583 [DEBUG] yandextank.core.tankcore tankcore.py:422	Collecting file: validation_error.yaml to /var/loadtest/logs/2020-04-20_09-13-33.435105/validation_error.yaml
2020-04-20 09:13:33,586 [WARNING] yandextank.core.tankcore tankcore.py:424	File not found to collect: validation_error.yaml
2020-04-20 09:13:33,588 [DEBUG] yandextank.core.tankcore tankcore.py:422	Collecting file: /var/loadtest/logs/2020-04-20_09-13-33.435105/phantom_abaCmT.log to /var/loadtest/logs/2020-04-20_09-13-33.435105/phantom_abaCmT.log
2020-04-20 09:13:33,592 [WARNING] yandextank.core.tankcore tankcore.py:429	File already exists: /var/loadtest/logs/2020-04-20_09-13-33.435105/phantom_abaCmT.log
